<?xml version="1.0"?>
<sdf version="1.8">
  <model name="custom_drone">
    <pose>0 0 0 0 0 0</pose>
    <link name="base_link">
      <inertial>
        <pose>-1.054264181030751e-07 0.0025919260853499893 -0.026708763818450765 0 0 0</pose>
        <mass>2.1650499079872736</mass>
        <inertia>
          <ixx>0.024339</ixx>
          <ixy>0</ixy>
          <ixz>0</ixz>
          <iyy>0.043382</iyy>
          <iyz>-4e-06</iyz>
          <izz>0.02453</izz>
        </inertia>
      </inertial>
      <visual name="base_visual">
        <pose>0 0 0 0 0 0</pose>
        <geometry>
          <mesh>
            <uri>file:///home/fwd/Desktop/custom_sdf/meshes/base_link.stl</uri>
            <scale>0.001 0.001 0.001</scale>
          </mesh>
        </geometry>
        <material>
          <ambient>0.8 0.8 0.8 1</ambient>
          <diffuse>0.8 0.8 0.8 1</diffuse>
          <specular>0.8 0.8 0.8 1</specular>
        </material>
      </visual>
      <collision name="base_collision">
        <pose>0 0 0 0 0 0</pose>
        <geometry>
          <mesh>
            <uri>file:///home/fwd/Desktop/custom_sdf/meshes/base_link.stl</uri>
            <scale>0.001 0.001 0.001</scale>
          </mesh>
        </geometry>
        <surface>
          <contact>
            <ode>
              <max_vel>100.0</max_vel>
              <min_depth>0.001</min_depth>
            </ode>
          </contact>
          <friction>
            <ode>
              <mu>100000.0</mu>
              <mu2>100000.0</mu2>
            </ode>
          </friction>
        </surface>
        <self_collide>true</self_collide>
      </collision>

      <gravity>1</gravity>
      <velocity_decay />
      <self_collide>true</self_collide>
    </link>

    <!-- IMU LINK -->
    <link name='imu_link'>
      <inertial>
        <pose>0 0 0 0 0 0</pose>
        <mass>0.15</mass>
        <inertia>
          <ixx>0.00001</ixx>
          <ixy>0</ixy>
          <ixz>0</ixz>
          <iyy>0.00002</iyy>
          <iyz>0</iyz>
          <izz>0.00002</izz>
        </inertia>
      </inertial>
      <sensor name="imu_sensor" type="imu">
        <pose>0 0 0 3.14159 0 0</pose> <!-- 180 degrees in radians -->
        <always_on>true</always_on>
        <update_rate>1000.0</update_rate>
      </sensor>
    </link>

    <joint name='imu_joint' type='revolute'>
      <child>imu_link</child>
      <parent>base_link</parent>
      <axis>
        <xyz>0 0 1</xyz>
        <limit>
          <lower>0</lower>
          <upper>0</upper>
          <effort>0</effort>
          <velocity>0</velocity>
        </limit>
        <dynamics>
          <damping>1.0</damping>
        </dynamics>
      </axis>
    </joint>

    <!-- Rotor 1 -->
    <link name="Prop_1_1">
      <pose>2.5766354744272135e-08 0.005337611696938263 -1.0046815390740704e-07 0 0 0</pose>
      <inertial>
        <pose>0 0 0 0 0 0</pose>
        <mass>0.14132994757152942</mass>
        <inertia>
          <ixx>5e-06</ixx>
          <iyy>0.000527</iyy>
          <izz>0.000523</izz>
          <ixy>-0.0</ixy>
          <iyz>0.0</iyz>
          <ixz>-2e-06</ixz>
        </inertia>
      </inertial>
      <visual name="Prop_1_1_visual">
        <pose>0 0 0 0 0 0</pose>
        <geometry>
          <mesh>
            <uri>file:///home/fwd/Desktop/custom_sdf/meshes/Prop_1_1.stl</uri>
            <scale>0.001 0.001 0.001</scale>
          </mesh>
        </geometry>
        <material>
          <ambient>0 0 1</ambient>
          <diffuse>0 0 1</diffuse>
          <specular>1 1 1 1</specular>
          <pbr>
            <metal>
              <metalness>0.5</metalness>
              <roughness>0.5</roughness>
            </metal>
          </pbr>
        </material>
        <self_collide>true</self_collide>
      </visual>
      <collision name="Prop_1_1_collision">
        <pose>0 0 0 0 0 0</pose>
        <geometry>
          <mesh>
            <uri>file:///home/fwd/Desktop/custom_sdf/meshes/Prop_1_1.stl</uri>
            <scale>0.001 0.001 0.001</scale>
          </mesh>
        </geometry>
      </collision>
      <gravity>true</gravity>
    </link>

    <joint name="Revolute 1" type="revolute">
      <pose>0.159099 0.050384 0.132271 0 0 0</pose>
      <child>Prop_1_1</child>
      <parent>base_link</parent>
      <axis>
        <xyz>0 1 0</xyz>
        <limit>
          <lower>-1e+16</lower>
          <upper>1e+16</upper>
        </limit>
        <dynamics>
          <damping>0.004</damping>
        </dynamics>
      </axis>
      <physics>
        <ode>
          <implicit_spring_damper>true</implicit_spring_damper>
        </ode>
      </physics>
    </joint>
    <!-- Prop 2 -->
    <link name="Prop_2_1">
      <pose>1.818072214998523e-08 0.005335376367456207 -1.4559709513028984e-07 0 0 0</pose>
      <inertial>
        <pose>0 0 0 0 0 0</pose>
        <mass>0.14132994757152942</mass>
        <inertia>
          <ixx>5e-06</ixx>
          <iyy>0.000527</iyy>
          <izz>0.000523</izz>
          <ixy>-0.0</ixy>
          <iyz>0.0</iyz>
          <ixz>-2e-06</ixz>
        </inertia>
      </inertial>
      <visual name="Prop_2_1_visual">
        <pose>0 0 0 0 0 0</pose>
        <geometry>
          <mesh>
            <uri>file:///home/fwd/Desktop/custom_sdf/meshes/Prop_2_1.stl</uri>
            <scale>0.001 0.001 0.001</scale>
          </mesh>
        </geometry>
        <material>
          <ambient>0 1 0</ambient>
          <diffuse>0 1 0</diffuse>
          <specular>1 1 1 1</specular>
          <pbr>
            <metal>
              <metalness>0.5</metalness>
              <roughness>0.5</roughness>
            </metal>
          </pbr>
        </material>
        <self_collide>true</self_collide>
      </visual>
      <collision name="Prop_2_1_collision">
        <pose>0 0 0 0 0 0</pose>
        <geometry>
          <mesh>
            <uri>file:///home/fwd/Desktop/custom_sdf/meshes/Prop_2_1.stl</uri>
            <scale>0.001 0.001 0.001</scale>
          </mesh>
        </geometry>
      </collision>
      <gravity>true</gravity>
    </link>

    <joint name="Revolute 2" type="revolute">
      <pose>0.159099 0.050384 -0.185927 0 0 0</pose>
      <child>Prop_2_1</child>
      <parent>base_link</parent>
      <axis>
        <xyz>0 1 0</xyz>
        <limit>
          <lower>-1e+16</lower>
          <upper>1e+16</upper>
        </limit>
        <dynamics>
          <damping>0.004</damping>
        </dynamics>
      </axis>
      <physics>
        <ode>
          <implicit_spring_damper>true</implicit_spring_damper>
        </ode>
      </physics>
    </joint>

 <!-- Prop 3 -->
 <link name="Prop_3_1">
  <pose relative_to="base_link">-2.5766359240675385e-08 0.005337611696938541 -1.520021011558459e-07 0 0 0</pose>
  <inertial>
    <pose>0 0 0 0 0 0</pose>
    <mass>0.14132994757152942</mass>
    <inertia>
      <ixx>5e-06</ixx>
      <iyy>0.000527</iyy>
      <izz>0.000523</izz>
      <ixy>-0.0</ixy>
      <iyz>0.0</iyz>
      <ixz>-2e-06</ixz>
    </inertia>
  </inertial>
  <visual name="Prop_3_1_visual">
    <pose>0 0 0 0 0 0</pose>
    <geometry>
      <mesh>
        <uri>file:///home/fwd/Desktop/custom_sdf/meshes/Prop_3_1.stl</uri>
        <scale>0.001 0.001 0.001</scale>
      </mesh>
    </geometry>
    <material>
      <ambient>0 1 0</ambient>
      <diffuse>0 1 0</diffuse>
      <specular>1 1 1 1</specular>
      <pbr>
        <metal>
          <metalness>0.5</metalness>
          <roughness>0.5</roughness>
        </metal>
      </pbr>
    </material>
    <self_collide>true</self_collide>
  </visual>
  <collision name="Prop_3_1_collision">
    <pose>0 0 0 0 0 0</pose>
    <geometry>
      <mesh>
        <uri>file:///home/fwd/Desktop/custom_sdf/meshes/Prop_3_1.stl</uri>
        <scale>0.001 0.001 0.001</scale>
      </mesh>
    </geometry>
  </collision>
  <gravity>true</gravity>
</link>

<joint name="Revolute 3" type="revolute">
  <pose relative_to="base_link">-0.159099 0.050384 -0.185927 0 0 0</pose>
  <child>Prop_3_1</child>
  <parent>base_link</parent>
  <axis>
    <xyz>0 1 0</xyz>
    <limit>
      <lower>-1e+16</lower>
      <upper>1e+16</upper>
    </limit>
    <dynamics>
      <damping>0.004</damping>
    </dynamics>
  </axis>
  <physics>
    <ode>
      <implicit_spring_damper>true</implicit_spring_damper>
    </ode>
  </physics>
</joint>








    <!-- Prop 4 -->
    <link name="Prop_4_1">
      <pose relative_to="base_link">-6.971467014782462e-08 0.005335376367455964 -9.406438186698729e-08 0 0 0</pose>
      <inertial>
        <pose>0 0 0 0 0 0</pose>
        <mass>0.14132994757152942</mass>
        <inertia>
          <ixx>5e-06</ixx>
          <iyy>0.000527</iyy>
          <izz>0.000523</izz>
          <ixy>-0.0</ixy>
          <iyz>0.0</iyz>
          <ixz>-2e-06</ixz>
        </inertia>
      </inertial>
      <visual name="Prop_4_1_visual">
        <pose>0 0 0 0 0 0</pose>
        <geometry>
          <mesh>
            <uri>file:///home/fwd/Desktop/custom_sdf/meshes/Prop_4_1.stl</uri>
            <scale>0.001 0.001 0.001</scale>
          </mesh>
        </geometry>
        <material>
          <ambient>0 1 0</ambient>
          <diffuse>0 1 0</diffuse>
          <specular>1 1 1 1</specular>
          <pbr>
            <metal>
              <metalness>0.5</metalness>
              <roughness>0.5</roughness>
            </metal>
          </pbr>
        </material>
        <self_collide>true</self_collide>
      </visual>
      <collision name="Prop_4_1_collision">
        <pose>0 0 0 0 0 0</pose>
        <geometry>
          <mesh>
            <uri>file:///home/fwd/Desktop/custom_sdf/meshes/Prop_4_1.stl</uri>
            <scale>0.001 0.001 0.001</scale>
          </mesh>
        </geometry>
      </collision>
      <gravity>true</gravity>
    </link>

    <joint name="Revolute 4" type="revolute">
      <pose relative_to="base_link">-0.159099 0.050384 0.132271 0 0 0</pose>
      <child>Prop_4_1</child>
      <parent>base_link</parent>
      <axis>
        <xyz>0 1 0</xyz>
        <limit>
          <lower>-1e+16</lower>
          <upper>1e+16</upper>
        </limit>
        <dynamics>
          <damping>0.004</damping>
        </dynamics>
      </axis>
      <physics>
        <ode>
          <implicit_spring_damper>true</implicit_spring_damper>
        </ode>
      </physics>
    </joint>
   
  </model>
</sdf>